<?xml version='1.0' encoding='utf-8'?>
<mujoco model="gen3_scene">
  <compiler angle="radian" autolimits="true" />
  <default>
    <geom friction="1.0 0.01 0.0001" solref="0.02 1" solimp="0.9 0.95 0.001" margin="0.001" condim="4" />
    <joint damping="1.0" armature="0.01" />
  </default>
  <option timestep="0.002" gravity="0 0 -9.81" integrator="RK4" impratio="20" density="1.2" viscosity="2e-05" cone="elliptic" />
  <size njmax="5000" nconmax="5000" />
  <visual>
    <global offwidth="1920" offheight="1080" fovy="59" />
    <map znear="0.001" />
  </visual>
  <asset>
    <texture type="skybox" colorspace="auto" builtin="gradient" rgb1="0.9 0.9 1" rgb2="0.2 0.3 0.4" width="256" height="1536" />
    <texture type="2d" colorspace="sRGB" name="texplane" file="textures/light-gray-floor-tile.png" />
    <texture type="2d" colorspace="sRGB" name="tex-wood" file="textures/light_wood.png" />
    <texture type="cube" colorspace="linear" name="tex-steel-brushed" file="textures/steel-brushed.png" />
    <texture type="2d" colorspace="linear" name="tex-light-gray-plaster" file="textures/light-gray-plaster.png" />
    <texture name="teddy_tex_png" type="2d" file="objects/teddy_bear/10607_teddy_bear_SG_v1_diffuse.png" />
    <texture name="cardboard_tex" type="2d" file="objects/Cardboard box/6857659-light-brown-wallpaper.png" />
    <mesh name="base_link" content_type="model/stl" file="robot/base_link.stl" />
    <mesh name="shoulder_link" content_type="model/stl" file="robot/shoulder_link.stl" />
    <mesh name="half_arm_1_link" content_type="model/stl" file="robot/half_arm_1_link.stl" />
    <mesh name="half_arm_2_link" content_type="model/stl" file="robot/half_arm_2_link.stl" />
    <mesh name="forearm_link" content_type="model/stl" file="robot/forearm_link.stl" />
    <mesh name="spherical_wrist_1_link" content_type="model/stl" file="robot/spherical_wrist_1_link.stl" />
    <mesh name="spherical_wrist_2_link" content_type="model/stl" file="robot/spherical_wrist_2_link.stl" />
    <mesh name="bracelet_no_vision_link" content_type="model/stl" file="robot/bracelet_no_vision_link.stl" />
    <mesh name="robotiq_base" content_type="model/stl" file="robot/robotiq_base.stl" />
    <mesh name="left_knuckle" content_type="model/stl" file="robot/left_knuckle.stl" />
    <mesh name="right_knuckle" content_type="model/stl" file="robot/right_knuckle.stl" />
    <mesh name="left_finger" content_type="model/stl" file="robot/left_finger.stl" />
    <mesh name="right_finger" content_type="model/stl" file="robot/right_finger.stl" />
    <mesh name="left_inner_knuckle" content_type="model/stl" file="robot/left_inner_knuckle.stl" />
    <mesh name="right_inner_knuckle" content_type="model/stl" file="robot/right_inner_knuckle.stl" />
    <mesh name="left_finger_tip" content_type="model/stl" file="robot/left_finger_tip.stl" />
    <mesh name="right_finger_tip" content_type="model/stl" file="robot/right_finger_tip.stl" />
    <mesh name="bracelet_with_vision_link" content_type="model/stl" file="robot/bracelet_with_vision_link.stl" />
    <mesh name="teddy_mesh" file="objects/teddy_bear/teddy3.obj" scale="0.01 0.01 0.01" />
    <mesh name="teddy_mesh_small" file="objects/teddy_bear/teddy3.obj" scale="0.006 0.006 0.006" />
    <mesh name="cardboard_mesh" file="objects/Cardboard box/Cardboard box.obj" scale="0.15 0.15 0.15" />
    <material name="floorplane" texture="texplane" texuniform="true" texrepeat="2 2" specular="0" shininess="0" reflectance="0.01" />
    <material name="table_wood" texture="tex-wood" texuniform="true" texrepeat="1 1" specular="0.35" shininess="0.4" reflectance="0.15" />
    <material name="table_legs_metal" texture="tex-steel-brushed" shininess="0.8" reflectance="0.8" />
    <material name="walls_mat" texture="tex-light-gray-plaster" texuniform="true" texrepeat="3 3" specular="0.1" shininess="0.1" />
    <material name="teddy_mat_png" texture="teddy_tex_png" specular="0.05" shininess="0.2" />
    <material name="cardboard_mat" texture="cardboard_tex" texuniform="true" specular="0.05" shininess="0.2" />
    <mesh name="big_bear_col_mesh_part_00" file="objects/_convex_parts/big_bear/big_bear_00.stl" />
    <mesh name="big_bear_col_mesh_part_01" file="objects/_convex_parts/big_bear/big_bear_01.stl" />
    <mesh name="big_bear_col_mesh_part_02" file="objects/_convex_parts/big_bear/big_bear_02.stl" />
    <mesh name="big_bear_col_mesh_part_03" file="objects/_convex_parts/big_bear/big_bear_03.stl" />
    <mesh name="big_bear_col_mesh_part_04" file="objects/_convex_parts/big_bear/big_bear_04.stl" />
    <mesh name="big_bear_col_mesh_part_05" file="objects/_convex_parts/big_bear/big_bear_05.stl" />
    <mesh name="big_bear_col_mesh_part_06" file="objects/_convex_parts/big_bear/big_bear_06.stl" />
    <mesh name="big_bear_col_mesh_part_07" file="objects/_convex_parts/big_bear/big_bear_07.stl" />
    <mesh name="big_bear_col_mesh_part_08" file="objects/_convex_parts/big_bear/big_bear_08.stl" />
    <mesh name="big_bear_col_mesh_part_09" file="objects/_convex_parts/big_bear/big_bear_09.stl" />
    <mesh name="big_bear_col_mesh_part_10" file="objects/_convex_parts/big_bear/big_bear_10.stl" />
    <mesh name="big_bear_col_mesh_part_11" file="objects/_convex_parts/big_bear/big_bear_11.stl" />
    <mesh name="big_bear_col_mesh_part_12" file="objects/_convex_parts/big_bear/big_bear_12.stl" />
    <mesh name="big_bear_col_mesh_part_13" file="objects/_convex_parts/big_bear/big_bear_13.stl" />
    <mesh name="big_bear_col_mesh_part_14" file="objects/_convex_parts/big_bear/big_bear_14.stl" />
    <mesh name="big_bear_col_mesh_part_15" file="objects/_convex_parts/big_bear/big_bear_15.stl" />
    <mesh name="small_bear_col_mesh_part_00" file="objects/_convex_parts/small_bear/small_bear_00.stl" />
    <mesh name="small_bear_col_mesh_part_01" file="objects/_convex_parts/small_bear/small_bear_01.stl" />
    <mesh name="small_bear_col_mesh_part_02" file="objects/_convex_parts/small_bear/small_bear_02.stl" />
    <mesh name="small_bear_col_mesh_part_03" file="objects/_convex_parts/small_bear/small_bear_03.stl" />
    <mesh name="small_bear_col_mesh_part_04" file="objects/_convex_parts/small_bear/small_bear_04.stl" />
    <mesh name="small_bear_col_mesh_part_05" file="objects/_convex_parts/small_bear/small_bear_05.stl" />
    <mesh name="small_bear_col_mesh_part_06" file="objects/_convex_parts/small_bear/small_bear_06.stl" />
    <mesh name="small_bear_col_mesh_part_07" file="objects/_convex_parts/small_bear/small_bear_07.stl" />
    <mesh name="small_bear_col_mesh_part_08" file="objects/_convex_parts/small_bear/small_bear_08.stl" />
    <mesh name="small_bear_col_mesh_part_09" file="objects/_convex_parts/small_bear/small_bear_09.stl" />
    <mesh name="small_bear_col_mesh_part_10" file="objects/_convex_parts/small_bear/small_bear_10.stl" />
    <mesh name="small_bear_col_mesh_part_11" file="objects/_convex_parts/small_bear/small_bear_11.stl" />
    <mesh name="cardboard_col_mesh_part_00" file="objects/_convex_parts/cardboard_box/cardboard_box_00.stl" />
    <mesh name="cardboard_col_mesh_part_01" file="objects/_convex_parts/cardboard_box/cardboard_box_01.stl" />
    <mesh name="cardboard_col_mesh_part_02" file="objects/_convex_parts/cardboard_box/cardboard_box_02.stl" />
    <mesh name="cardboard_col_mesh_part_03" file="objects/_convex_parts/cardboard_box/cardboard_box_03.stl" />
    <mesh name="cardboard_col_mesh_part_04" file="objects/_convex_parts/cardboard_box/cardboard_box_04.stl" />
    <mesh name="cardboard_col_mesh_part_05" file="objects/_convex_parts/cardboard_box/cardboard_box_05.stl" />
    <mesh name="cardboard_col_mesh_part_06" file="objects/_convex_parts/cardboard_box/cardboard_box_06.stl" />
    <mesh name="cardboard_col_mesh_part_07" file="objects/_convex_parts/cardboard_box/cardboard_box_07.stl" />
    <mesh name="cardboard_col_mesh_part_08" file="objects/_convex_parts/cardboard_box/cardboard_box_08.stl" />
    <mesh name="cardboard_col_mesh_part_09" file="objects/_convex_parts/cardboard_box/cardboard_box_09.stl" />
    <mesh name="cardboard_col_mesh_part_10" file="objects/_convex_parts/cardboard_box/cardboard_box_10.stl" />
    <mesh name="cardboard_col_mesh_part_11" file="objects/_convex_parts/cardboard_box/cardboard_box_11.stl" />
    <mesh name="base_col_mesh_part_00" file="robot/_convex_parts/gen3_mount/gen3_mount_00.stl" />
    <mesh name="base_col_mesh_part_01" file="robot/_convex_parts/gen3_mount/gen3_mount_01.stl" />
    <mesh name="base_col_mesh_part_02" file="robot/_convex_parts/gen3_mount/gen3_mount_02.stl" />
    <mesh name="base_col_mesh_part_03" file="robot/_convex_parts/gen3_mount/gen3_mount_03.stl" />
    <mesh name="shoulder_col_mesh_part_00" file="robot/_convex_parts/gen3_shoulder_link/gen3_shoulder_link_00.stl" />
    <mesh name="shoulder_col_mesh_part_01" file="robot/_convex_parts/gen3_shoulder_link/gen3_shoulder_link_01.stl" />
    <mesh name="shoulder_col_mesh_part_02" file="robot/_convex_parts/gen3_shoulder_link/gen3_shoulder_link_02.stl" />
    <mesh name="shoulder_col_mesh_part_03" file="robot/_convex_parts/gen3_shoulder_link/gen3_shoulder_link_03.stl" />
    <mesh name="shoulder_col_mesh_part_04" file="robot/_convex_parts/gen3_shoulder_link/gen3_shoulder_link_04.stl" />
    <mesh name="shoulder_col_mesh_part_05" file="robot/_convex_parts/gen3_shoulder_link/gen3_shoulder_link_05.stl" />
    <mesh name="upperarm_col_mesh_part_00" file="robot/_convex_parts/gen3_half_arm_1_link/gen3_half_arm_1_link_00.stl" />
    <mesh name="upperarm_col_mesh_part_01" file="robot/_convex_parts/gen3_half_arm_1_link/gen3_half_arm_1_link_01.stl" />
    <mesh name="upperarm_col_mesh_part_02" file="robot/_convex_parts/gen3_half_arm_1_link/gen3_half_arm_1_link_02.stl" />
    <mesh name="upperarm_col_mesh_part_03" file="robot/_convex_parts/gen3_half_arm_1_link/gen3_half_arm_1_link_03.stl" />
    <mesh name="upperarm_col_mesh_part_04" file="robot/_convex_parts/gen3_half_arm_1_link/gen3_half_arm_1_link_04.stl" />
    <mesh name="upperarm_col_mesh_part_05" file="robot/_convex_parts/gen3_half_arm_1_link/gen3_half_arm_1_link_05.stl" />
    <mesh name="upperarm_col_mesh_part_06" file="robot/_convex_parts/gen3_half_arm_1_link/gen3_half_arm_1_link_06.stl" />
    <mesh name="upperarm_col_mesh_part_07" file="robot/_convex_parts/gen3_half_arm_1_link/gen3_half_arm_1_link_07.stl" />
    <mesh name="upperarm2_col_mesh_part_00" file="robot/_convex_parts/gen3_half_arm_2_link/gen3_half_arm_2_link_00.stl" />
    <mesh name="upperarm2_col_mesh_part_01" file="robot/_convex_parts/gen3_half_arm_2_link/gen3_half_arm_2_link_01.stl" />
    <mesh name="upperarm2_col_mesh_part_02" file="robot/_convex_parts/gen3_half_arm_2_link/gen3_half_arm_2_link_02.stl" />
    <mesh name="upperarm2_col_mesh_part_03" file="robot/_convex_parts/gen3_half_arm_2_link/gen3_half_arm_2_link_03.stl" />
    <mesh name="upperarm2_col_mesh_part_04" file="robot/_convex_parts/gen3_half_arm_2_link/gen3_half_arm_2_link_04.stl" />
    <mesh name="upperarm2_col_mesh_part_05" file="robot/_convex_parts/gen3_half_arm_2_link/gen3_half_arm_2_link_05.stl" />
    <mesh name="upperarm2_col_mesh_part_06" file="robot/_convex_parts/gen3_half_arm_2_link/gen3_half_arm_2_link_06.stl" />
    <mesh name="upperarm2_col_mesh_part_07" file="robot/_convex_parts/gen3_half_arm_2_link/gen3_half_arm_2_link_07.stl" />
    <mesh name="forearm_col_mesh_part_00" file="robot/_convex_parts/gen3_forearm_link/gen3_forearm_link_00.stl" />
    <mesh name="forearm_col_mesh_part_01" file="robot/_convex_parts/gen3_forearm_link/gen3_forearm_link_01.stl" />
    <mesh name="forearm_col_mesh_part_02" file="robot/_convex_parts/gen3_forearm_link/gen3_forearm_link_02.stl" />
    <mesh name="forearm_col_mesh_part_03" file="robot/_convex_parts/gen3_forearm_link/gen3_forearm_link_03.stl" />
    <mesh name="forearm_col_mesh_part_04" file="robot/_convex_parts/gen3_forearm_link/gen3_forearm_link_04.stl" />
    <mesh name="forearm_col_mesh_part_05" file="robot/_convex_parts/gen3_forearm_link/gen3_forearm_link_05.stl" />
    <mesh name="forearm_col_mesh_part_06" file="robot/_convex_parts/gen3_forearm_link/gen3_forearm_link_06.stl" />
    <mesh name="forearm_col_mesh_part_07" file="robot/_convex_parts/gen3_forearm_link/gen3_forearm_link_07.stl" />
    <mesh name="wrist1_col_mesh_part_00" file="robot/_convex_parts/gen3_spherical_wrist_1_link/gen3_spherical_wrist_1_link_00.stl" />
    <mesh name="wrist1_col_mesh_part_01" file="robot/_convex_parts/gen3_spherical_wrist_1_link/gen3_spherical_wrist_1_link_01.stl" />
    <mesh name="wrist1_col_mesh_part_02" file="robot/_convex_parts/gen3_spherical_wrist_1_link/gen3_spherical_wrist_1_link_02.stl" />
    <mesh name="wrist1_col_mesh_part_03" file="robot/_convex_parts/gen3_spherical_wrist_1_link/gen3_spherical_wrist_1_link_03.stl" />
    <mesh name="wrist1_col_mesh_part_04" file="robot/_convex_parts/gen3_spherical_wrist_1_link/gen3_spherical_wrist_1_link_04.stl" />
    <mesh name="wrist1_col_mesh_part_05" file="robot/_convex_parts/gen3_spherical_wrist_1_link/gen3_spherical_wrist_1_link_05.stl" />
    <mesh name="wrist2_col_mesh_part_00" file="robot/_convex_parts/gen3_spherical_wrist_2_link/gen3_spherical_wrist_2_link_00.stl" />
    <mesh name="wrist2_col_mesh_part_01" file="robot/_convex_parts/gen3_spherical_wrist_2_link/gen3_spherical_wrist_2_link_01.stl" />
    <mesh name="wrist2_col_mesh_part_02" file="robot/_convex_parts/gen3_spherical_wrist_2_link/gen3_spherical_wrist_2_link_02.stl" />
    <mesh name="wrist2_col_mesh_part_03" file="robot/_convex_parts/gen3_spherical_wrist_2_link/gen3_spherical_wrist_2_link_03.stl" />
    <mesh name="wrist2_col_mesh_part_04" file="robot/_convex_parts/gen3_spherical_wrist_2_link/gen3_spherical_wrist_2_link_04.stl" />
    <mesh name="wrist2_col_mesh_part_05" file="robot/_convex_parts/gen3_spherical_wrist_2_link/gen3_spherical_wrist_2_link_05.stl" />
    <mesh name="bracelet_col_mesh_part_00" file="robot/_convex_parts/gen3_bracelet_link/gen3_bracelet_link_00.stl" />
    <mesh name="bracelet_col_mesh_part_01" file="robot/_convex_parts/gen3_bracelet_link/gen3_bracelet_link_01.stl" />
    <mesh name="bracelet_col_mesh_part_02" file="robot/_convex_parts/gen3_bracelet_link/gen3_bracelet_link_02.stl" />
    <mesh name="bracelet_col_mesh_part_03" file="robot/_convex_parts/gen3_bracelet_link/gen3_bracelet_link_03.stl" />
    <mesh name="bracelet_col_mesh_part_04" file="robot/_convex_parts/gen3_bracelet_link/gen3_bracelet_link_04.stl" />
    <mesh name="bracelet_col_mesh_part_05" file="robot/_convex_parts/gen3_bracelet_link/gen3_bracelet_link_05.stl" />
    <mesh name="robotiq_base_col_mesh_part_00" file="robot/_convex_parts/gen3_bracelet_link/gen3_bracelet_link_00.stl" />
    <mesh name="robotiq_base_col_mesh_part_01" file="robot/_convex_parts/gen3_bracelet_link/gen3_bracelet_link_01.stl" />
    <mesh name="robotiq_base_col_mesh_part_02" file="robot/_convex_parts/gen3_bracelet_link/gen3_bracelet_link_02.stl" />
    <mesh name="robotiq_base_col_mesh_part_03" file="robot/_convex_parts/gen3_bracelet_link/gen3_bracelet_link_03.stl" />
    <mesh name="robotiq_base_col_mesh_part_04" file="robot/_convex_parts/gen3_bracelet_link/gen3_bracelet_link_04.stl" />
    <mesh name="robotiq_base_col_mesh_part_05" file="robot/_convex_parts/gen3_bracelet_link/gen3_bracelet_link_05.stl" />
  </asset>
  <worldbody>
    <geom name="floor" size="3 3 0.125" type="plane" group="1" material="floorplane" />
    <geom name="wall_leftcorner_visual" size="1.06 1.5 0.01" pos="-1.25  2.25 1.5" quat="0.653281 0.653281 0.270598 0.270598" type="box" contype="0" conaffinity="0" group="1" material="walls_mat" />
    <geom name="wall_rightcorner_visual" size="1.06 1.5 0.01" pos="-1.25 -2.25 1.5" quat="0.653281 0.653281 -0.270598 -0.270598" type="box" contype="0" conaffinity="0" group="1" material="walls_mat" />
    <geom name="wall_left_visual" size="1.75 1.5 0.01" pos=" 1.25  3.0 1.5" quat="0.707107 0.707107 0 0" type="box" contype="0" conaffinity="0" group="1" material="walls_mat" />
    <geom name="wall_right_visual" size="1.75 1.5 0.01" pos=" 1.25 -3.0 1.5" quat="0.707107 -0.707107 0 0" type="box" contype="0" conaffinity="0" group="1" material="walls_mat" />
    <geom name="wall_rear_visual" size="1.5 1.5 0.01" pos="-2.0  0.0 1.5" quat="0.5 0.5 0.5 0.5" type="box" contype="0" conaffinity="0" group="1" material="walls_mat" />
    <geom name="wall_front_visual" size="3.0 1.5 0.01" pos=" 3.0  0.0 1.5" quat="0.5 0.5 -0.5 -0.5" type="box" contype="0" conaffinity="0" group="1" material="walls_mat" />
    <camera name="frontview" pos="1.6 0 1.45" quat="0.560842 0.430646 0.430646 0.560842" />
    <camera name="birdview" pos="-0.2 0 3" quat="0.707107 0 0 0.707107" />
    <camera name="agentview" pos="0.5 0 1.35" quat="0.653098 0.271041 0.271041 0.653098" />
    <camera name="sideview" pos="-0.0565177 1.27612 1.48796" quat="0.00990507 0.00687796 0.591223 0.806418" />
    <camera name="wrist_rgb" mode="fixed" pos="0 0 0" quat="1 0 0 0" fovy="60" />
    <camera name="fixed_down" mode="fixed" pos="0.10 0.50 1.7868" quat="0.6830127 0.1830127 0.1830127 0.6830127" fovy="60" />
    <body name="fixed_cam_rig" pos="0.20 0.50 0.72">
      <geom name="fixed_cam_baseplate" type="cylinder" size="0.06 0.01" pos="0.05 0 0" rgba="0.15 0.15 0.15 1" contype="0" conaffinity="0" group="1" />
      <geom name="fixed_cam_pole" type="capsule" fromto="0.05 0 0   0.05 0 1.0668" size="0.012" rgba="0.2 0.2 0.2 1" contype="0" conaffinity="0" group="1" />
      <geom name="fixed_cam_arm" type="capsule" fromto="0.05 0 1.0668   -0.05 0 1.0668" size="0.010" rgba="0.2 0.2 0.2 1" contype="0" conaffinity="0" group="1" />
      <geom name="fixed_cam_box" type="box" pos="-0.05 0 1.0668" size="0.04 0.025 0.02" rgba="0.05 0.05 0.05 1" contype="0" conaffinity="0" group="1" />
      <geom name="fixed_cam_lens" type="cylinder" pos="-0.05 0 1.0368" quat="0.9659 0 0.2588 0" size="0.01 0.02" rgba="0.12 0.12 0.12 1" contype="0" conaffinity="0" group="1" />
    </body>
    <light pos="1 1 1.5" dir="-0.19245 -0.19245 -0.96225" type="directional" castshadow="false" />
    <body name="arena_table_left" pos="-0.35 0.3 0.695">
      <geom name="table_left_collision" size="0.4 0.8 0.025" type="box" contype="1" conaffinity="1" rgba="0.5 0.5 0 1" />
      <geom name="table_left_visual" size="0.4 0.8 0.025" type="box" contype="0" conaffinity="0" group="1" material="table_wood" />
      <geom name="table_left_leg1_visual" size="0.025 0.3875" pos=" 0.3  0.7 -0.3875" type="cylinder" contype="0" conaffinity="0" group="1" material="table_legs_metal" />
      <geom name="table_left_leg2_visual" size="0.025 0.3875" pos="-0.3  0.7 -0.3875" type="cylinder" contype="0" conaffinity="0" group="1" material="table_legs_metal" />
      <geom name="table_left_leg3_visual" size="0.025 0.3875" pos="-0.3 -0.7 -0.3875" type="cylinder" contype="0" conaffinity="0" group="1" material="table_legs_metal" />
      <geom name="table_left_leg4_visual" size="0.025 0.3875" pos=" 0.3 -0.7 -0.3875" type="cylinder" contype="0" conaffinity="0" group="1" material="table_legs_metal" />
    </body>
    <body name="arena_table_right" pos="0.6 0.3 0.695">
      <geom name="table_right_collision" size="0.4 0.8 0.025" type="box" contype="1" conaffinity="1" rgba="0.5 0.5 0 1" />
      <geom name="table_right_visual" size="0.4 0.8 0.025" type="box" contype="0" conaffinity="0" group="1" material="table_wood" />
      <geom name="table_right_leg1_visual" size="0.025 0.3875" pos=" 0.3  0.7 -0.3875" type="cylinder" contype="0" conaffinity="0" group="1" material="table_legs_metal" />
      <geom name="table_right_leg2_visual" size="0.025 0.3875" pos="-0.3  0.7 -0.3875" type="cylinder" contype="0" conaffinity="0" group="1" material="table_legs_metal" />
      <geom name="table_right_leg3_visual" size="0.025 0.3875" pos="-0.3 -0.7 -0.3875" type="cylinder" contype="0" conaffinity="0" group="1" material="table_legs_metal" />
      <geom name="table_right_leg4_visual" size="0.025 0.3875" pos=" 0.3 -0.7 -0.3875" type="cylinder" contype="0" conaffinity="0" group="1" material="table_legs_metal" />
    </body>
    <body name="big_bear" pos="-0.45 0.10 0.71">
      <freejoint />
      <geom type="mesh" mesh="teddy_mesh" material="teddy_mat_png" contype="0" conaffinity="0" />
      <geom name="big_bear_col_part_00" type="mesh" mesh="big_bear_col_mesh_part_00" contype="1" conaffinity="1" density="10.0" rgba="1 0.2 0.2 0.18" />
      <geom name="big_bear_col_part_01" type="mesh" mesh="big_bear_col_mesh_part_01" contype="1" conaffinity="1" density="10.0" rgba="1 0.2 0.2 0.18" />
      <geom name="big_bear_col_part_02" type="mesh" mesh="big_bear_col_mesh_part_02" contype="1" conaffinity="1" density="10.0" rgba="1 0.2 0.2 0.18" />
      <geom name="big_bear_col_part_03" type="mesh" mesh="big_bear_col_mesh_part_03" contype="1" conaffinity="1" density="10.0" rgba="1 0.2 0.2 0.18" />
      <geom name="big_bear_col_part_04" type="mesh" mesh="big_bear_col_mesh_part_04" contype="1" conaffinity="1" density="10.0" rgba="1 0.2 0.2 0.18" />
      <geom name="big_bear_col_part_05" type="mesh" mesh="big_bear_col_mesh_part_05" contype="1" conaffinity="1" density="10.0" rgba="1 0.2 0.2 0.18" />
      <geom name="big_bear_col_part_06" type="mesh" mesh="big_bear_col_mesh_part_06" contype="1" conaffinity="1" density="10.0" rgba="1 0.2 0.2 0.18" />
      <geom name="big_bear_col_part_07" type="mesh" mesh="big_bear_col_mesh_part_07" contype="1" conaffinity="1" density="10.0" rgba="1 0.2 0.2 0.18" />
      <geom name="big_bear_col_part_08" type="mesh" mesh="big_bear_col_mesh_part_08" contype="1" conaffinity="1" density="10.0" rgba="1 0.2 0.2 0.18" />
      <geom name="big_bear_col_part_09" type="mesh" mesh="big_bear_col_mesh_part_09" contype="1" conaffinity="1" density="10.0" rgba="1 0.2 0.2 0.18" />
      <geom name="big_bear_col_part_10" type="mesh" mesh="big_bear_col_mesh_part_10" contype="1" conaffinity="1" density="10.0" rgba="1 0.2 0.2 0.18" />
      <geom name="big_bear_col_part_11" type="mesh" mesh="big_bear_col_mesh_part_11" contype="1" conaffinity="1" density="10.0" rgba="1 0.2 0.2 0.18" />
      <geom name="big_bear_col_part_12" type="mesh" mesh="big_bear_col_mesh_part_12" contype="1" conaffinity="1" density="10.0" rgba="1 0.2 0.2 0.18" />
      <geom name="big_bear_col_part_13" type="mesh" mesh="big_bear_col_mesh_part_13" contype="1" conaffinity="1" density="10.0" rgba="1 0.2 0.2 0.18" />
      <geom name="big_bear_col_part_14" type="mesh" mesh="big_bear_col_mesh_part_14" contype="1" conaffinity="1" density="10.0" rgba="1 0.2 0.2 0.18" />
      <geom name="big_bear_col_part_15" type="mesh" mesh="big_bear_col_mesh_part_15" contype="1" conaffinity="1" density="10.0" rgba="1 0.2 0.2 0.18" />
    </body>
    <body name="small_bear" pos="-0.40 0.50 0.71">
      <freejoint />
      <geom type="mesh" mesh="teddy_mesh_small" material="teddy_mat_png" contype="0" conaffinity="0" />
      <geom name="small_bear_col_part_00" type="mesh" mesh="small_bear_col_mesh_part_00" contype="1" conaffinity="1" density="10.0" rgba="0.2 0.6 1 0.18" />
      <geom name="small_bear_col_part_01" type="mesh" mesh="small_bear_col_mesh_part_01" contype="1" conaffinity="1" density="10.0" rgba="0.2 0.6 1 0.18" />
      <geom name="small_bear_col_part_02" type="mesh" mesh="small_bear_col_mesh_part_02" contype="1" conaffinity="1" density="10.0" rgba="0.2 0.6 1 0.18" />
      <geom name="small_bear_col_part_03" type="mesh" mesh="small_bear_col_mesh_part_03" contype="1" conaffinity="1" density="10.0" rgba="0.2 0.6 1 0.18" />
      <geom name="small_bear_col_part_04" type="mesh" mesh="small_bear_col_mesh_part_04" contype="1" conaffinity="1" density="10.0" rgba="0.2 0.6 1 0.18" />
      <geom name="small_bear_col_part_05" type="mesh" mesh="small_bear_col_mesh_part_05" contype="1" conaffinity="1" density="10.0" rgba="0.2 0.6 1 0.18" />
      <geom name="small_bear_col_part_06" type="mesh" mesh="small_bear_col_mesh_part_06" contype="1" conaffinity="1" density="10.0" rgba="0.2 0.6 1 0.18" />
      <geom name="small_bear_col_part_07" type="mesh" mesh="small_bear_col_mesh_part_07" contype="1" conaffinity="1" density="10.0" rgba="0.2 0.6 1 0.18" />
      <geom name="small_bear_col_part_08" type="mesh" mesh="small_bear_col_mesh_part_08" contype="1" conaffinity="1" density="10.0" rgba="0.2 0.6 1 0.18" />
      <geom name="small_bear_col_part_09" type="mesh" mesh="small_bear_col_mesh_part_09" contype="1" conaffinity="1" density="10.0" rgba="0.2 0.6 1 0.18" />
      <geom name="small_bear_col_part_10" type="mesh" mesh="small_bear_col_mesh_part_10" contype="1" conaffinity="1" density="10.0" rgba="0.2 0.6 1 0.18" />
      <geom name="small_bear_col_part_11" type="mesh" mesh="small_bear_col_mesh_part_11" contype="1" conaffinity="1" density="10.0" rgba="0.2 0.6 1 0.18" />
    </body>
    <body name="cardboard_box" pos="-0.1 0.40 0.85" euler="0 1.5708 1.5708">
      <freejoint />
      <geom type="mesh" mesh="cardboard_mesh" material="cardboard_mat" contype="0" conaffinity="0" />
      <geom name="cardboard_col_part_00" type="mesh" mesh="cardboard_col_mesh_part_00" contype="1" conaffinity="1" density="5.0" rgba="0.2 1 0.4 0.18" />
      <geom name="cardboard_col_part_01" type="mesh" mesh="cardboard_col_mesh_part_01" contype="1" conaffinity="1" density="5.0" rgba="0.2 1 0.4 0.18" />
      <geom name="cardboard_col_part_02" type="mesh" mesh="cardboard_col_mesh_part_02" contype="1" conaffinity="1" density="5.0" rgba="0.2 1 0.4 0.18" />
      <geom name="cardboard_col_part_03" type="mesh" mesh="cardboard_col_mesh_part_03" contype="1" conaffinity="1" density="5.0" rgba="0.2 1 0.4 0.18" />
      <geom name="cardboard_col_part_04" type="mesh" mesh="cardboard_col_mesh_part_04" contype="1" conaffinity="1" density="5.0" rgba="0.2 1 0.4 0.18" />
      <geom name="cardboard_col_part_05" type="mesh" mesh="cardboard_col_mesh_part_05" contype="1" conaffinity="1" density="5.0" rgba="0.2 1 0.4 0.18" />
      <geom name="cardboard_col_part_06" type="mesh" mesh="cardboard_col_mesh_part_06" contype="1" conaffinity="1" density="5.0" rgba="0.2 1 0.4 0.18" />
      <geom name="cardboard_col_part_07" type="mesh" mesh="cardboard_col_mesh_part_07" contype="1" conaffinity="1" density="5.0" rgba="0.2 1 0.4 0.18" />
      <geom name="cardboard_col_part_08" type="mesh" mesh="cardboard_col_mesh_part_08" contype="1" conaffinity="1" density="5.0" rgba="0.2 1 0.4 0.18" />
      <geom name="cardboard_col_part_09" type="mesh" mesh="cardboard_col_mesh_part_09" contype="1" conaffinity="1" density="5.0" rgba="0.2 1 0.4 0.18" />
      <geom name="cardboard_col_part_10" type="mesh" mesh="cardboard_col_mesh_part_10" contype="1" conaffinity="1" density="5.0" rgba="0.2 1 0.4 0.18" />
      <geom name="cardboard_col_part_11" type="mesh" mesh="cardboard_col_mesh_part_11" contype="1" conaffinity="1" density="5.0" rgba="0.2 1 0.4 0.18" />
    </body>
    <body name="gen3_mount" pos="0 0 0.72" gravcomp="1">
      <geom type="mesh" mesh="base_link" contype="0" conaffinity="0" />
      <body name="gen3_shoulder_link" pos="0 0 0.15643" quat="-3.67321e-06 1 0 0">
        <inertial pos="-2.3e-05 -0.010364 -0.07336" quat="0.707051 0.0451246 -0.0453544 0.704263" mass="1.3773" diaginertia="0.00488868 0.00457 0.00135132" />
        <joint name="gen3_joint_1" pos="0 0 0" axis="0 0 1" actuatorfrcrange="-80 80" />
        <geom type="mesh" rgba="0.75294 0.75294 0.75294 1" mesh="shoulder_link" contype="0" conaffinity="0" />
        <body name="gen3_half_arm_1_link" pos="0 0.005375 -0.12838" quat="0.707105 0.707108 0 0">
          <inertial pos="-4.4e-05 -0.09958 -0.013278" quat="0.482348 0.516286 -0.516862 0.483366" mass="1.1636" diaginertia="0.0113017 0.011088 0.00102532" />
          <joint name="gen3_joint_2" pos="0 0 0" axis="0 0 1" range="-2.41 2.41" actuatorfrcrange="-80 80" />
          <geom type="mesh" rgba="0.75294 0.75294 0.75294 1" mesh="half_arm_1_link" contype="0" conaffinity="0" />
          <body name="gen3_half_arm_2_link" pos="0 -0.21038 -0.006375" quat="0.707105 -0.707108 0 0">
            <inertial pos="-4.4e-05 -0.006641 -0.117892" quat="0.706144 0.0213722 -0.0209128 0.707437" mass="1.1636" diaginertia="0.0111633 0.010932 0.00100671" />
            <joint name="gen3_joint_3" pos="0 0 0" axis="0 0 1" actuatorfrcrange="-80 80" />
            <geom type="mesh" rgba="0.75294 0.75294 0.75294 1" mesh="half_arm_2_link" contype="0" conaffinity="0" />
            <body name="gen3_forearm_link" pos="0 0.006375 -0.21038" quat="0.707105 0.707108 0 0">
              <inertial pos="-1.8e-05 -0.075478 -0.015006" quat="0.483678 0.515961 -0.515859 0.483455" mass="0.9302" diaginertia="0.00834839 0.008147 0.000598606" />
              <joint name="gen3_joint_4" pos="0 0 0" axis="0 0 1" range="-2.66 2.66" actuatorfrcrange="-80 80" />
              <geom type="mesh" rgba="0.75294 0.75294 0.75294 1" mesh="forearm_link" contype="0" conaffinity="0" />
              <body name="gen3_spherical_wrist_1_link" pos="0 -0.20843 -0.006375" quat="0.707105 -0.707108 0 0">
                <inertial pos="1e-06 -0.009432 -0.063883" quat="0.703558 0.0707492 -0.0707492 0.703558" mass="0.6781" diaginertia="0.00165901 0.001596 0.000346988" />
                <joint name="gen3_joint_5" pos="0 0 0" axis="0 0 1" actuatorfrcrange="-20 20" />
                <geom type="mesh" rgba="0.75294 0.75294 0.75294 1" mesh="spherical_wrist_1_link" contype="0" conaffinity="0" />
                <body name="gen3_spherical_wrist_2_link" pos="0 0.00017505 -0.10593" quat="0.707105 0.707108 0 0">
                  <inertial pos="1e-06 -0.045483 -0.00965" quat="0.44426 0.550121 -0.550121 0.44426" mass="0.6781" diaginertia="0.00170087 0.001641 0.00035013" />
                  <joint name="gen3_joint_6" pos="0 0 0" axis="0 0 1" range="-2.23 2.23" actuatorfrcrange="-20 20" />
                  <geom type="mesh" rgba="0.75294 0.75294 0.75294 1" mesh="spherical_wrist_2_link" contype="0" conaffinity="0" />
                  <body name="gen3_bracelet_link" pos="0 -0.10593 -0.00017505" quat="0.707105 -0.707108 0 0">
                    <inertial pos="0.000967136 0.00592216 -0.0302303" quat="0.707949 0.693027 -0.101455 0.0907149" mass="1.5992" diaginertia="0.00562397 0.00533749 0.00190074" />
                    <joint name="gen3_joint_7" pos="0 0 0" axis="0 0 1" actuatorfrcrange="-20 20" />
                    <geom type="mesh" rgba="0.75294 0.75294 0.75294 1" mesh="bracelet_no_vision_link" contype="0" conaffinity="0" />
                    <geom type="mesh" mesh="bracelet_with_vision_link" contype="0" conaffinity="0" />
                    <geom pos="0 0 -0.061525" quat="0 1 0 0" type="mesh" mesh="robotiq_base" contype="0" conaffinity="0" />
                    <body name="gen3_robotiq_85_left_knuckle_link" pos="0.0306011 0 -0.11643" quat="0 1 0 0">
                      <inertial pos="0.0280921 -0.000550523 0.00570126" quat="0.699112 0.212074 0.213677 0.648544" mass="0.0564515" diaginertia="1.95637e-05 1.76663e-05 9.3792e-06" />
                      <joint name="gen3_robotiq_85_left_knuckle_joint" pos="0 0 0" axis="0 -1 0" range="0 0.8" actuatorfrcrange="-50 50" />
                      <geom type="mesh" mesh="left_knuckle" contype="0" conaffinity="0" />
                      <geom pos="0.0315262 0 -0.00376347" type="mesh" mesh="left_finger" contype="0" conaffinity="0" />
                      <geom name="left_knuckle_col" type="capsule" fromto="0.02 0 0   0.06 0 0" size="0.015" rgba="1 0 0 0" contype="1" conaffinity="1" />
                      <body name="gen3_robotiq_85_left_finger_tip_link" pos="0.0371575 0 0.0434217">
                        <inertial pos="-0.0145671 -0.0008 0.016497" quat="0.977773 0 -0.209665 0" mass="0.0426859" diaginertia="1.20653e-05 1.19789e-05 2.64405e-06" />
                        <joint name="gen3_robotiq_85_left_finger_tip_joint" pos="0 0 0" axis="0 -1 0" />
                        <geom type="mesh" mesh="left_finger_tip" contype="0" conaffinity="0" />
                        <geom name="left_fingertip_col" type="sphere" pos="0 0 0.02" size="0.012" rgba="1 0 0 0" contype="1" conaffinity="1" />
                      </body>
                    </body>
                    <body name="gen3_robotiq_85_right_knuckle_link" pos="-0.0306011 0 -0.11643" quat="0 1 0 0">
                      <inertial pos="-0.0280921 4.48872e-05 0.00570126" quat="0.669099 -0.212862 -0.212522 0.679581" mass="0.0564515" diaginertia="1.95514e-05 1.7665e-05 9.37296e-06" />
                      <joint name="gen3_robotiq_85_right_knuckle_joint" pos="0 0 0" axis="0 -1 0" range="-0.8 0" actuatorfrcrange="-50 50" />
                      <geom type="mesh" mesh="right_knuckle" contype="0" conaffinity="0" />
                      <geom pos="-0.0315262 0 -0.00376347" type="mesh" mesh="right_finger" contype="0" conaffinity="0" />
                      <geom name="right_knuckle_col" type="capsule" fromto="-0.02 0 0   -0.06 0 0" size="0.015" rgba="1 0 0 0" contype="1" conaffinity="1" />
                      <body name="gen3_robotiq_85_right_finger_tip_link" pos="-0.0371575 0 0.0434217">
                        <inertial pos="0.0145671 5e-05 0.016497" quat="0.977773 0 0.209665 0" mass="0.0426859" diaginertia="1.20653e-05 1.19789e-05 2.64405e-06" />
                        <joint name="gen3_robotiq_85_right_finger_tip_joint" pos="0 0 0" axis="0 -1 0" />
                        <geom type="mesh" mesh="right_finger_tip" contype="0" conaffinity="0" />
                        <geom name="right_fingertip_col" type="sphere" pos="0 0 0.02" size="0.012" rgba="1 0 0 0" contype="1" conaffinity="1" />
                      </body>
                    </body>
                    <body name="gen3_robotiq_85_left_inner_knuckle_link" pos="0.0127 0 -0.122945" quat="0 1 0 0">
                      <inertial pos="0.018977 0.00015001 0.022471" quat="0.939613 0 0.342237 0" mass="0.0296938" diaginertia="1.28757e-05 8.69056e-06 4.88712e-06" />
                      <joint name="gen3_robotiq_85_left_inner_knuckle_joint" pos="0 0 0" axis="0 -1 0" />
                      <geom type="mesh" mesh="left_inner_knuckle" contype="0" conaffinity="0" />
                      <geom type="sphere" size="0.012" pos="0 0 0.02" rgba="1 0 0 0" contype="1" conaffinity="1" />
                    </body>
                    <body name="gen3_robotiq_85_right_inner_knuckle_link" pos="-0.0127 0 -0.122945" quat="0 1 0 0">
                      <inertial pos="-0.0192682 5.001e-05 0.0222218" quat="0.936371 0 -0.351012 0" mass="0.0296938" diaginertia="1.2882e-05 8.69056e-06 4.88076e-06" />
                      <joint name="gen3_robotiq_85_right_inner_knuckle_joint" pos="0 0 0" axis="0 -1 0" />
                      <geom type="mesh" mesh="right_inner_knuckle" contype="0" conaffinity="0" />
                      <geom type="sphere" size="0.012" pos="0 0 0.02" rgba="1 0 0 0" contype="1" conaffinity="1" />
                    </body>
                    <geom name="bracelet_col_part_00" type="mesh" mesh="bracelet_col_mesh_part_00" contype="1" conaffinity="1" density="1000.0" rgba="1 0.9 0.2 0.12" />
                    <geom name="bracelet_col_part_01" type="mesh" mesh="bracelet_col_mesh_part_01" contype="1" conaffinity="1" density="1000.0" rgba="1 0.9 0.2 0.12" />
                    <geom name="bracelet_col_part_02" type="mesh" mesh="bracelet_col_mesh_part_02" contype="1" conaffinity="1" density="1000.0" rgba="1 0.9 0.2 0.12" />
                    <geom name="bracelet_col_part_03" type="mesh" mesh="bracelet_col_mesh_part_03" contype="1" conaffinity="1" density="1000.0" rgba="1 0.9 0.2 0.12" />
                    <geom name="bracelet_col_part_04" type="mesh" mesh="bracelet_col_mesh_part_04" contype="1" conaffinity="1" density="1000.0" rgba="1 0.9 0.2 0.12" />
                    <geom name="bracelet_col_part_05" type="mesh" mesh="bracelet_col_mesh_part_05" contype="1" conaffinity="1" density="1000.0" rgba="1 0.9 0.2 0.12" />
                    <geom name="robotiq_base_col_part_00" type="mesh" mesh="robotiq_base_col_mesh_part_00" contype="1" conaffinity="1" density="1000.0" rgba="1 0.8 0.2 0.12" pos="0 0 -0.061525" quat="0 1 0 0" />
                    <geom name="robotiq_base_col_part_01" type="mesh" mesh="robotiq_base_col_mesh_part_01" contype="1" conaffinity="1" density="1000.0" rgba="1 0.8 0.2 0.12" pos="0 0 -0.061525" quat="0 1 0 0" />
                    <geom name="robotiq_base_col_part_02" type="mesh" mesh="robotiq_base_col_mesh_part_02" contype="1" conaffinity="1" density="1000.0" rgba="1 0.8 0.2 0.12" pos="0 0 -0.061525" quat="0 1 0 0" />
                    <geom name="robotiq_base_col_part_03" type="mesh" mesh="robotiq_base_col_mesh_part_03" contype="1" conaffinity="1" density="1000.0" rgba="1 0.8 0.2 0.12" pos="0 0 -0.061525" quat="0 1 0 0" />
                    <geom name="robotiq_base_col_part_04" type="mesh" mesh="robotiq_base_col_mesh_part_04" contype="1" conaffinity="1" density="1000.0" rgba="1 0.8 0.2 0.12" pos="0 0 -0.061525" quat="0 1 0 0" />
                    <geom name="robotiq_base_col_part_05" type="mesh" mesh="robotiq_base_col_mesh_part_05" contype="1" conaffinity="1" density="1000.0" rgba="1 0.8 0.2 0.12" pos="0 0 -0.061525" quat="0 1 0 0" />
                  </body>
                  <geom name="wrist2_col_part_00" type="mesh" mesh="wrist2_col_mesh_part_00" contype="1" conaffinity="1" density="1000.0" rgba="1 0.9 0.2 0.12" />
                  <geom name="wrist2_col_part_01" type="mesh" mesh="wrist2_col_mesh_part_01" contype="1" conaffinity="1" density="1000.0" rgba="1 0.9 0.2 0.12" />
                  <geom name="wrist2_col_part_02" type="mesh" mesh="wrist2_col_mesh_part_02" contype="1" conaffinity="1" density="1000.0" rgba="1 0.9 0.2 0.12" />
                  <geom name="wrist2_col_part_03" type="mesh" mesh="wrist2_col_mesh_part_03" contype="1" conaffinity="1" density="1000.0" rgba="1 0.9 0.2 0.12" />
                  <geom name="wrist2_col_part_04" type="mesh" mesh="wrist2_col_mesh_part_04" contype="1" conaffinity="1" density="1000.0" rgba="1 0.9 0.2 0.12" />
                  <geom name="wrist2_col_part_05" type="mesh" mesh="wrist2_col_mesh_part_05" contype="1" conaffinity="1" density="1000.0" rgba="1 0.9 0.2 0.12" />
                </body>
                <geom name="wrist1_col_part_00" type="mesh" mesh="wrist1_col_mesh_part_00" contype="1" conaffinity="1" density="1000.0" rgba="1 0.9 0.2 0.12" />
                <geom name="wrist1_col_part_01" type="mesh" mesh="wrist1_col_mesh_part_01" contype="1" conaffinity="1" density="1000.0" rgba="1 0.9 0.2 0.12" />
                <geom name="wrist1_col_part_02" type="mesh" mesh="wrist1_col_mesh_part_02" contype="1" conaffinity="1" density="1000.0" rgba="1 0.9 0.2 0.12" />
                <geom name="wrist1_col_part_03" type="mesh" mesh="wrist1_col_mesh_part_03" contype="1" conaffinity="1" density="1000.0" rgba="1 0.9 0.2 0.12" />
                <geom name="wrist1_col_part_04" type="mesh" mesh="wrist1_col_mesh_part_04" contype="1" conaffinity="1" density="1000.0" rgba="1 0.9 0.2 0.12" />
                <geom name="wrist1_col_part_05" type="mesh" mesh="wrist1_col_mesh_part_05" contype="1" conaffinity="1" density="1000.0" rgba="1 0.9 0.2 0.12" />
              </body>
              <geom name="forearm_col_part_00" type="mesh" mesh="forearm_col_mesh_part_00" contype="1" conaffinity="1" density="1000.0" rgba="1 0.9 0.2 0.12" />
              <geom name="forearm_col_part_01" type="mesh" mesh="forearm_col_mesh_part_01" contype="1" conaffinity="1" density="1000.0" rgba="1 0.9 0.2 0.12" />
              <geom name="forearm_col_part_02" type="mesh" mesh="forearm_col_mesh_part_02" contype="1" conaffinity="1" density="1000.0" rgba="1 0.9 0.2 0.12" />
              <geom name="forearm_col_part_03" type="mesh" mesh="forearm_col_mesh_part_03" contype="1" conaffinity="1" density="1000.0" rgba="1 0.9 0.2 0.12" />
              <geom name="forearm_col_part_04" type="mesh" mesh="forearm_col_mesh_part_04" contype="1" conaffinity="1" density="1000.0" rgba="1 0.9 0.2 0.12" />
              <geom name="forearm_col_part_05" type="mesh" mesh="forearm_col_mesh_part_05" contype="1" conaffinity="1" density="1000.0" rgba="1 0.9 0.2 0.12" />
              <geom name="forearm_col_part_06" type="mesh" mesh="forearm_col_mesh_part_06" contype="1" conaffinity="1" density="1000.0" rgba="1 0.9 0.2 0.12" />
              <geom name="forearm_col_part_07" type="mesh" mesh="forearm_col_mesh_part_07" contype="1" conaffinity="1" density="1000.0" rgba="1 0.9 0.2 0.12" />
            </body>
            <geom name="upperarm2_col_part_00" type="mesh" mesh="upperarm2_col_mesh_part_00" contype="1" conaffinity="1" density="1000.0" rgba="1 0.9 0.2 0.12" />
            <geom name="upperarm2_col_part_01" type="mesh" mesh="upperarm2_col_mesh_part_01" contype="1" conaffinity="1" density="1000.0" rgba="1 0.9 0.2 0.12" />
            <geom name="upperarm2_col_part_02" type="mesh" mesh="upperarm2_col_mesh_part_02" contype="1" conaffinity="1" density="1000.0" rgba="1 0.9 0.2 0.12" />
            <geom name="upperarm2_col_part_03" type="mesh" mesh="upperarm2_col_mesh_part_03" contype="1" conaffinity="1" density="1000.0" rgba="1 0.9 0.2 0.12" />
            <geom name="upperarm2_col_part_04" type="mesh" mesh="upperarm2_col_mesh_part_04" contype="1" conaffinity="1" density="1000.0" rgba="1 0.9 0.2 0.12" />
            <geom name="upperarm2_col_part_05" type="mesh" mesh="upperarm2_col_mesh_part_05" contype="1" conaffinity="1" density="1000.0" rgba="1 0.9 0.2 0.12" />
            <geom name="upperarm2_col_part_06" type="mesh" mesh="upperarm2_col_mesh_part_06" contype="1" conaffinity="1" density="1000.0" rgba="1 0.9 0.2 0.12" />
            <geom name="upperarm2_col_part_07" type="mesh" mesh="upperarm2_col_mesh_part_07" contype="1" conaffinity="1" density="1000.0" rgba="1 0.9 0.2 0.12" />
          </body>
          <geom name="upperarm_col_part_00" type="mesh" mesh="upperarm_col_mesh_part_00" contype="1" conaffinity="1" density="1000.0" rgba="1 0.9 0.2 0.12" />
          <geom name="upperarm_col_part_01" type="mesh" mesh="upperarm_col_mesh_part_01" contype="1" conaffinity="1" density="1000.0" rgba="1 0.9 0.2 0.12" />
          <geom name="upperarm_col_part_02" type="mesh" mesh="upperarm_col_mesh_part_02" contype="1" conaffinity="1" density="1000.0" rgba="1 0.9 0.2 0.12" />
          <geom name="upperarm_col_part_03" type="mesh" mesh="upperarm_col_mesh_part_03" contype="1" conaffinity="1" density="1000.0" rgba="1 0.9 0.2 0.12" />
          <geom name="upperarm_col_part_04" type="mesh" mesh="upperarm_col_mesh_part_04" contype="1" conaffinity="1" density="1000.0" rgba="1 0.9 0.2 0.12" />
          <geom name="upperarm_col_part_05" type="mesh" mesh="upperarm_col_mesh_part_05" contype="1" conaffinity="1" density="1000.0" rgba="1 0.9 0.2 0.12" />
          <geom name="upperarm_col_part_06" type="mesh" mesh="upperarm_col_mesh_part_06" contype="1" conaffinity="1" density="1000.0" rgba="1 0.9 0.2 0.12" />
          <geom name="upperarm_col_part_07" type="mesh" mesh="upperarm_col_mesh_part_07" contype="1" conaffinity="1" density="1000.0" rgba="1 0.9 0.2 0.12" />
        </body>
        <geom name="shoulder_col_part_00" type="mesh" mesh="shoulder_col_mesh_part_00" contype="1" conaffinity="1" density="1000.0" rgba="1 0.9 0.2 0.12" />
        <geom name="shoulder_col_part_01" type="mesh" mesh="shoulder_col_mesh_part_01" contype="1" conaffinity="1" density="1000.0" rgba="1 0.9 0.2 0.12" />
        <geom name="shoulder_col_part_02" type="mesh" mesh="shoulder_col_mesh_part_02" contype="1" conaffinity="1" density="1000.0" rgba="1 0.9 0.2 0.12" />
        <geom name="shoulder_col_part_03" type="mesh" mesh="shoulder_col_mesh_part_03" contype="1" conaffinity="1" density="1000.0" rgba="1 0.9 0.2 0.12" />
        <geom name="shoulder_col_part_04" type="mesh" mesh="shoulder_col_mesh_part_04" contype="1" conaffinity="1" density="1000.0" rgba="1 0.9 0.2 0.12" />
        <geom name="shoulder_col_part_05" type="mesh" mesh="shoulder_col_mesh_part_05" contype="1" conaffinity="1" density="1000.0" rgba="1 0.9 0.2 0.12" />
      </body>
      <geom name="base_col_part_00" type="mesh" mesh="base_col_mesh_part_00" contype="1" conaffinity="1" density="1000.0" rgba="1 0.9 0.2 0.12" />
      <geom name="base_col_part_01" type="mesh" mesh="base_col_mesh_part_01" contype="1" conaffinity="1" density="1000.0" rgba="1 0.9 0.2 0.12" />
      <geom name="base_col_part_02" type="mesh" mesh="base_col_mesh_part_02" contype="1" conaffinity="1" density="1000.0" rgba="1 0.9 0.2 0.12" />
      <geom name="base_col_part_03" type="mesh" mesh="base_col_mesh_part_03" contype="1" conaffinity="1" density="1000.0" rgba="1 0.9 0.2 0.12" />
    </body>
  </worldbody>
  <actuator>
    <position name="act_j1" joint="gen3_joint_1" kp="3000" kv="200" forcerange="-300 300" />
    <position name="act_j2" joint="gen3_joint_2" kp="3000" kv="200" forcerange="-300 300" />
    <position name="act_j3" joint="gen3_joint_3" kp="2500" kv="180" forcerange="-250 250" />
    <position name="act_j4" joint="gen3_joint_4" kp="4000" kv="250" forcerange="-400 400" />
    <position name="act_j5" joint="gen3_joint_5" kp="1200" kv="120" forcerange="-120 120" />
    <position name="act_j6" joint="gen3_joint_6" kp="1200" kv="120" forcerange="-120 120" />
    <position name="act_j7" joint="gen3_joint_7" kp="1000" kv="100" forcerange="-100 100" />
  </actuator>
</mujoco>